[2022-11-30T07:38:09.855+0000] {taskinstance.py:1165} INFO - Dependencies all met for <TaskInstance: _prcatice.lines_counter manual__2022-11-30T07:38:06.922783+00:00 [queued]>
[2022-11-30T07:38:09.861+0000] {taskinstance.py:1165} INFO - Dependencies all met for <TaskInstance: _prcatice.lines_counter manual__2022-11-30T07:38:06.922783+00:00 [queued]>
[2022-11-30T07:38:09.861+0000] {taskinstance.py:1362} INFO - 
--------------------------------------------------------------------------------
[2022-11-30T07:38:09.862+0000] {taskinstance.py:1363} INFO - Starting attempt 1 of 1
[2022-11-30T07:38:09.862+0000] {taskinstance.py:1364} INFO - 
--------------------------------------------------------------------------------
[2022-11-30T07:38:09.870+0000] {taskinstance.py:1383} INFO - Executing <Task(_PythonDecoratedOperator): lines_counter> on 2022-11-30 07:38:06.922783+00:00
[2022-11-30T07:38:09.873+0000] {standard_task_runner.py:55} INFO - Started process 175 to run task
[2022-11-30T07:38:09.878+0000] {standard_task_runner.py:82} INFO - Running: ['***', 'tasks', 'run', '_prcatice', 'lines_counter', 'manual__2022-11-30T07:38:06.922783+00:00', '--job-id', '679', '--raw', '--subdir', 'DAGS_FOLDER/practice.py', '--cfg-path', '/tmp/tmp5ul8ce_m']
[2022-11-30T07:38:09.878+0000] {standard_task_runner.py:83} INFO - Job 679: Subtask lines_counter
[2022-11-30T07:38:09.941+0000] {task_command.py:376} INFO - Running <TaskInstance: _prcatice.lines_counter manual__2022-11-30T07:38:06.922783+00:00 [running]> on host 0fcad1446026
[2022-11-30T07:38:09.988+0000] {taskinstance.py:1592} INFO - Exporting the following env vars:
AIRFLOW_CTX_DAG_OWNER=***
AIRFLOW_CTX_DAG_ID=_prcatice
AIRFLOW_CTX_TASK_ID=lines_counter
AIRFLOW_CTX_EXECUTION_DATE=2022-11-30T07:38:06.922783+00:00
AIRFLOW_CTX_TRY_NUMBER=1
AIRFLOW_CTX_DAG_RUN_ID=manual__2022-11-30T07:38:06.922783+00:00
[2022-11-30T07:38:09.989+0000] {taskinstance.py:1851} ERROR - Task failed with exception
Traceback (most recent call last):
  File "/home/airflow/.local/lib/python3.7/site-packages/airflow/decorators/base.py", line 188, in execute
    return_value = super().execute(context)
  File "/home/airflow/.local/lib/python3.7/site-packages/airflow/operators/python.py", line 175, in execute
    return_value = self.execute_callable()
  File "/home/airflow/.local/lib/python3.7/site-packages/airflow/operators/python.py", line 193, in execute_callable
    return self.python_callable(*self.op_args, **self.op_kwargs)
  File "/opt/airflow/dags/practice.py", line 15, in lines_counter
    with open(file_path, "r") as f:
FileNotFoundError: [Errno 2] No such file or directory: 'prcatice_file.csv'
[2022-11-30T07:38:09.993+0000] {taskinstance.py:1406} INFO - Marking task as FAILED. dag_id=_prcatice, task_id=lines_counter, execution_date=20221130T073806, start_date=20221130T073809, end_date=20221130T073809
[2022-11-30T07:38:10.012+0000] {standard_task_runner.py:105} ERROR - Failed to execute job 679 for task lines_counter ([Errno 2] No such file or directory: 'prcatice_file.csv'; 175)
[2022-11-30T07:38:10.049+0000] {local_task_job.py:159} INFO - Task exited with return code 1
[2022-11-30T07:38:10.060+0000] {taskinstance.py:2623} INFO - 0 downstream tasks scheduled from follow-on schedule check
