[2022-11-30T09:25:05.871+0000] {taskinstance.py:1165} INFO - Dependencies all met for <TaskInstance: pratice_pg.pg_prepare manual__2022-11-30T09:25:02.976939+00:00 [queued]>
[2022-11-30T09:25:05.876+0000] {taskinstance.py:1165} INFO - Dependencies all met for <TaskInstance: pratice_pg.pg_prepare manual__2022-11-30T09:25:02.976939+00:00 [queued]>
[2022-11-30T09:25:05.877+0000] {taskinstance.py:1362} INFO - 
--------------------------------------------------------------------------------
[2022-11-30T09:25:05.877+0000] {taskinstance.py:1363} INFO - Starting attempt 1 of 1
[2022-11-30T09:25:05.877+0000] {taskinstance.py:1364} INFO - 
--------------------------------------------------------------------------------
[2022-11-30T09:25:05.885+0000] {taskinstance.py:1383} INFO - Executing <Task(_PythonDecoratedOperator): pg_prepare> on 2022-11-30 09:25:02.976939+00:00
[2022-11-30T09:25:05.888+0000] {standard_task_runner.py:55} INFO - Started process 216 to run task
[2022-11-30T09:25:05.890+0000] {standard_task_runner.py:82} INFO - Running: ['***', 'tasks', 'run', 'pratice_pg', 'pg_prepare', 'manual__2022-11-30T09:25:02.976939+00:00', '--job-id', '706', '--raw', '--subdir', 'DAGS_FOLDER/practice_pg.py', '--cfg-path', '/tmp/tmp4frhen2o']
[2022-11-30T09:25:05.890+0000] {standard_task_runner.py:83} INFO - Job 706: Subtask pg_prepare
[2022-11-30T09:25:05.926+0000] {task_command.py:376} INFO - Running <TaskInstance: pratice_pg.pg_prepare manual__2022-11-30T09:25:02.976939+00:00 [running]> on host 481f60569de1
[2022-11-30T09:25:05.973+0000] {taskinstance.py:1592} INFO - Exporting the following env vars:
AIRFLOW_CTX_DAG_OWNER=***
AIRFLOW_CTX_DAG_ID=pratice_pg
AIRFLOW_CTX_TASK_ID=pg_prepare
AIRFLOW_CTX_EXECUTION_DATE=2022-11-30T09:25:02.976939+00:00
AIRFLOW_CTX_TRY_NUMBER=1
AIRFLOW_CTX_DAG_RUN_ID=manual__2022-11-30T09:25:02.976939+00:00
[2022-11-30T09:25:05.978+0000] {base.py:71} INFO - Using connection ID 'pgdb' for task execution.
[2022-11-30T09:25:06.091+0000] {base.py:71} INFO - Using connection ID 'pgdb' for task execution.
[2022-11-30T09:25:06.094+0000] {taskinstance.py:1851} ERROR - Task failed with exception
Traceback (most recent call last):
  File "/home/airflow/.local/lib/python3.7/site-packages/airflow/decorators/base.py", line 188, in execute
    return_value = super().execute(context)
  File "/home/airflow/.local/lib/python3.7/site-packages/airflow/operators/python.py", line 175, in execute
    return_value = self.execute_callable()
  File "/home/airflow/.local/lib/python3.7/site-packages/airflow/operators/python.py", line 193, in execute_callable
    return self.python_callable(*self.op_args, **self.op_kwargs)
  File "/opt/airflow/dags/practice_pg.py", line 27, in pg_prepare
    shutil.copy(file_path,file)
  File "/usr/local/lib/python3.7/shutil.py", line 248, in copy
    copyfile(src, dst, follow_symlinks=follow_symlinks)
  File "/usr/local/lib/python3.7/shutil.py", line 121, in copyfile
    with open(dst, 'wb') as fdst:
PermissionError: [Errno 13] Permission denied: '/opt/pg_dir/prcatice_file.csv'
[2022-11-30T09:25:06.102+0000] {taskinstance.py:1406} INFO - Marking task as FAILED. dag_id=pratice_pg, task_id=pg_prepare, execution_date=20221130T092502, start_date=20221130T092505, end_date=20221130T092506
[2022-11-30T09:25:06.109+0000] {standard_task_runner.py:105} ERROR - Failed to execute job 706 for task pg_prepare ([Errno 13] Permission denied: '/opt/pg_dir/prcatice_file.csv'; 216)
[2022-11-30T09:25:06.145+0000] {local_task_job.py:159} INFO - Task exited with return code 1
[2022-11-30T09:25:06.161+0000] {taskinstance.py:2623} INFO - 0 downstream tasks scheduled from follow-on schedule check
